Workbook

Sheet Tabla de contenido
A2: ESTANDARES Y CRITERIOS - AUTOEVALUCION 3100-2019
A3: RAZON SOCIAL: CLÍNICA LAS PEÑITAS S.A.S. MUNICIPIO: Sincelejo, Sucre (Cra. 25 No. 23-26, Av. Las Peñitas) SERVICIOS A PRESTAR: Servicio farmacéutico (mediana/alta complejidad, modalidad intramural). Estándares 11.1.1 a 11.1.7 evaluados desde el servicio farmacéutico. Elaborado Por: __________________________________ (BORRADOR - pendiente de verificación con evidencias)
A6: ESTANDARES Y CRITERIOS - AUTOEVALUCION 3100-2019 | B6: Servicio | C6: Páginas
A7: 11.1. ESTÁNDARES Y CRITERIOS APLICABLES A TODOS LOS SERVICIOS | B7: 11.1.1 TALENTO HUMANO | C7: 59 -61
B8: 11.1.2. INFRAESTRUCTURA | C8: 61 - 68
B9: 11.1.3. DOTACIÓN | C9: 68 - 71
B10: 11.1.4. MEDICAMENTOS, DISPOSITIVOS MÉDICOS E INSUMOS | C10: 71 - 73
B11: 11.1.5. PROCESOS PRIORITARIOS | C11: 73 - 77
B12: 11.1.6. HISTORIA CLÍNICA Y REGISTROS | C12: 77 - 79
B13: 11.1.7. INTERDEPENDENCIA | C13: 79
A14: 11.2. GRUPO CONSULTA EXTERNA | B14: 11.2.1. SERVICIO DE CONSULTA EXTERNA GENERAL | C14: 80-84
B15: 11.2.2. SERVICIO DE CONSULTA EXTERNA ESPECIALIZADA | C15: 85-88
B16: 11.2.3. SERVICIO DE VACUNACIÓN | C16: 88-91
B17: 11.2.4. SERVICIO DE SEGURIDAD Y SALUD EN EL TRABAJO | C17: 91-93
A18: 11.3. GRUPO APOYO DIAGNÓSTICO Y COMPLEMENTACIÓN TERAPÉUTICA | B18: 11.3.1. SERVICIO DE TERAPIAS | C18: 94-97
B19: 11.3.2. SERVICIO FARMACÉUTICO | C19: 97-101
B20: 11.3.3 SERVICIO DE RADIOLOGiA ODONTOLÓGICA | C20: 101-103
B21: 11.3.4 SERVICIO DE IMÁGENES DIAGNÓSTICAS | C21: 103-104
B22: 11.3.5 SERVICIO DE MEDICINA NUCLEAR | C22: 112-115
B23: 11.3.6 SERVICIO DE RADIOTERAPIA | C23: 116-119
B24: 11.3.7 SERVICIO DE QUIMIOTERAPIA | C24: 119-123
B25: 11.3.8 SERVICIO DE DIAGNÓSTICO VASCULAR | C25: 123-125
B26: 11.3.9 SERVICIO DE HEMODINAMIA E INTERVENCIONISMO | C26: 125-128
B27: 11.3.10 SERVICIO DE GESTIÓN PRE TRANSFUSIONAL | C27: 129-130
B28: 11.3.11. SERVICIO DE TOMA DE MUESTRAS DE LABORATORIO CLÍNICO
B29: 11.3.12 SERVICIO DE LABORATORIO CLÍNICO | C29: 132-135
B30: 11.3.13 SERVICIO DE TOMA DE MUESTRAS DE CUELLO UTERINO Y GINECOLÓGICAS | C30: 135-137
B31: 11.3.14 SERVICIO DE LABORATORIO DE CITOLOGiAS CERVICO-UTERINAS | C31: 137-138
B32: 11.3.15 SERVICIO DE LABORATORIO DE HISTOTECNOLOGIA | C32: 138-139
B33: 11.3.16 SERVICIO DE PATOLOGÍA | C33: 140-142
B34: 11.3.17 SERVICIO DE DIÁLISIS | C34: 142-146
A35: 11.4 GRUPO INTERNACIÓN | B35: 11.4.1 SERVICIO DE HOSPITALIZACIÓN | C35: 146-154
B36: 11.4.2 SERVICIO DE HOSPITALIZACIÓN PACIENTE CRÓNICO | C36: 154-162
B37: 11.4.3 SERVICIO DE CUIDADO BÁSICO NEONATAL | C37: 162-165
B38: 11.4.4 SERVICIO DE CUIDADO INTERMEDIO NEONATAL | C38: 165-168
B39: 11.4.5 SERVICIO DE CUIDADO INTENSIVO NEONATAL | C39: 168-172
B40: 11.4.6 SERVICIO DE CUIDADO INTERMEDIO PEDIÁTRICO | C40: 172-175
B41: 11.4.7 SERVICIO DE CUIDADO INTENSIVO PEDIÁTRICO | C41: 175-179
B42: 11.4.8 SERVICIO DE CUIDADO INTERMEDIO ADULTO | C42: 179-182
B43: 11.4.9 SERVICIO DE CUIDADO INTENSIVO ADULTOS | C43: 182-186
...

Sheet Revisión final SF
A1: PREAUDITORÍA DE HABILITACIÓN – SERVICIO FARMACÉUTICO – CLÍNICA LAS PEÑITAS S.A.S. (Sincelejo)
A2: Alcance | B2: Estándares 11.1.1 a 11.1.7 evaluados exclusivamente desde el Servicio Farmacéutico, y estándar específico 11.3.2 SF. Revisión documental de las respuestas registradas en el archivo; no incluye visita de campo.
A3: Base de la revisión | B3: Las respuestas evaluadas son el borrador de autoevaluación elaborado sin acceso a documentos ni registros de la clínica. Describen la evidencia que debería existir, no evidencia aportada. Por eso ningún criterio puede calificarse como "Cumple" en esta etapa.
A4: Correspondencia con la columna Estado | B4: Cumple → C | Cumple parcialmente, No cumple y No evidenciado → NC | No aplica → NA. El concepto completo está en la columna E "Concepto preauditoría (QF)" de cada hoja.
A5: Advertencia | B5: Este archivo es un instrumento de preauditoría interna. No debe radicarse como autoevaluación oficial: la columna Estado refleja la falta de evidencia, no necesariamente el incumplimiento real.
A7: RESULTADO POR ESTÁNDAR
A8: Talento humano | B8: No evidenciado: 6 | No aplica: 15 | Cumple: 0 | Cumple parcialmente: 0 | No cumple: 0
A9: Infraestructura | B9: No evidenciado: 40 | No aplica: 129 | Cumple: 0 | Cumple parcialmente: 0 | No cumple: 0
A10: Dotación | B10: No evidenciado: 11 | No aplica: 40 | Cumple: 0 | Cumple parcialmente: 0 | No cumple: 0
A11: Medicamentos, DM e insumos | B11: No evidenciado: 46 | No aplica: 5 | Cumple: 0 | Cumple parcialmente: 0 | No cumple: 0
A12: Procesos prioritarios | B12: No evidenciado: 22 | No aplica: 69 | Cumple: 0 | Cumple parcialmente: 0 | No cumple: 0
A13: Historia clínica y registros | B13: No evidenciado: 6 | No aplica: 45 | Cumple: 0 | Cumple parcialmente: 0 | No cumple: 0
A14: Interdependencia | B14: No evidenciado: 0 | No aplica: 5 | Cumple: 0 | Cumple parcialmente: 0 | No cumple: 0
A15: 11.3.2 Servicio farmacéutico | B15: No evidenciado: 24 | No aplica: 14 | Cumple: 0 | Cumple parcialmente: 0 | No cumple: 0
A17: 1. RESPUESTAS QUE DEBEN CORREGIRSE
A18: MD – Criterio 13 (convenio banco de sangre) | B18: Estaba en C. No corresponde al SF: la sangre y sus componentes no se gestionan en farmacia. Corregido a NA.
A19: MD – Criterio 15 (kit agentes químicos) | B19: Estaba en C. Se exige a transporte asistencial, APH y urgencias, no al SF. Corregido a NA.
A20: DOT – Criterio 15 (empaque cerrado sucio/limpio) | B20: Estaba en C. Se refiere a elementos sucios y limpios de los servicios quirúrgicos, de internación y de urgencias; el transporte de medicamentos se evalúa en MD 4.3. Corregido a NA.
A21: DOT – Criterios 1.1 a 1.6 (equipos biomédicos) | B21: La respuesta trata neveras, termohigrómetros y aire acondicionado como equipos biomédicos. Debe precisarse qué equipos del SF son biomédicos; el control de los demás equipos se soporta en el criterio 9 del SF.
A22: SF – Criterio 5.4 (almacenamiento) | B22: Fija rangos genéricos de temperatura y humedad; el criterio exige las condiciones del fabricante de cada producto. Reformular indicando los rangos definidos por producto y el control aplicado.
A23: INF – Criterios 8, 10, 11 / PP – 12.7 | B23: Respuestas condicionales ("si… marcar NA"). Una autoevaluación debe afirmar la condición real: indicar el piso donde funciona el SF, si hay ascensor o rampa, y quién gestiona los gases medicinales.
A24: Calificaciones NA basadas en supuestos | B24: TH 4.1-4.3 (práctica formativa), INF 3, 5-5.4, 6, 7, 9.1-9.4 y 38-40 (edificación y atención al público), MD 14 (fabricación de gases) y PP 16.1-16.3 (reúso de DM). Deben confirmarse con información real antes de sostener el NA.
A25: Complejidad del SF | B25: Toda la evaluación supone mediana/alta complejidad. Debe confirmarse en REPS; define el perfil del talento humano, las áreas y la exigencia de dosis unitaria (SF criterios 1, 7, 13 y 17).
A27: 2. RESPUESTAS QUE REQUIEREN EVIDENCIA DOCUMENTAL (prioridad alta)
A28: Talento humano SF | B28: Hojas de vida del QF director técnico, regentes y auxiliares: títulos, tarjeta profesional, ReTHUS, certificados de aptitud ocupacional, inducción, reinducción y capacitación. Estudio de cargas y cuadros de turno 24 h.
A29: Medicamentos de control especial | B29: Resolución vigente del Fondo Rotatorio de Estupefacientes de Sucre, libro oficial actualizado, informes mensuales y procedimiento.
A30: Cadena de frío y condiciones ambientales | B30: Registros de temperatura y humedad (farmacia, bodega, stocks, neveras), certificados de calibración de termohigrómetros, plan de contingencia y evidencia de acciones ante desviaciones.
A31: Procesos generales del SF | B31: Manual de procesos y procedimientos bajo control documental firmado por el QF: selección, adquisición, recepción, almacenamiento, distribución, dispensación, devolución, disposición final.
A32: Comité de Farmacia y Terapéutica | B32: Acto de conformación, actas y listado básico de medicamentos aprobado.
A33: Farmacovigilancia y tecnovigilancia | B33: Programas, inscripción en las redes del INVIMA, referente designado y reportes realizados.
A34: Seguridad en el uso de medicamentos | B34: Listados de alto riesgo y LASA, doble verificación, conciliación, reporte y análisis de errores de medicación con planes de mejora.
A35: Registros sanitarios | B35: Consulta en INVIMA, con fecha, sobre una muestra de medicamentos y dispositivos médicos.
A36: Recepción técnica y disposición final | B36: Actas de recepción diligenciadas, contrato con gestor de residuos peligrosos y actas de destrucción.
A37: Carros de paro | B37: Listado aprobado según morbilidad y listas de chequeo diligenciadas.
A39: 3. CRITERIOS QUE REQUIEREN VERIFICACIÓN EN CAMPO
A40: Áreas del SF (SF 5.1-5.8) | B40: Delimitación y señalización de administración, recepción, dispensación, almacenamiento, control especial, rechazados/devueltos, vencidos y cuarentena.
A41: Condiciones locativas | B41: Pisos, paredes y techos lavables, sin humedad; ventilación y aire acondicionado; circulación libre; uso de estibas.
A42: Almacenamiento | B42: Separación de piso y paredes, segregación de alto riesgo y LASA con señalización, rotación FEFO, ausencia de vencidos en estanterías y stocks.
A43: Control especial | B43: Mueble o área con seguridad y acceso restringido; cuadre del inventario físico contra el libro oficial.
A44: Cadena de frío | B44: Neveras exclusivas, termómetro o data logger, temperatura actual dentro de 2-8 °C, respaldo con planta eléctrica.
...

Sheet Consolidado
B3: Estándares y criterios aplicables a todos los servicios | C3: Total criterios | D3: C | E3: NC | F3: NA | G3: Cumplimiento
B4: TS - Talento Humano | C4: 21 | D4: ='11.1.1TH'!C30 | E4: ='11.1.1TH'!C31 | F4: ='11.1.1TH'!C32 | G4: =D4/(C4-F4)
B5: TS - Infraestructura | C5: 167 | D5: ='11.1.2.INF'!C202 | E5: ='11.1.2.INF'!C203 | F5: ='11.1.2.INF'!C204 | G5: =D5/(C5-F5)
B6: TS - Dotación | C6: 52 | D6: ='11.1.3.DOT'!C68 | E6: ='11.1.3.DOT'!C69 | F6: ='11.1.3.DOT'!C70 | G6: =D6/(C6-F6)
B7: TS - Medicamentos, dispositivos médicos e insumos | C7: 51 | D7: ='11.1.4MD'!C65 | E7: ='11.1.4MD'!C66 | F7: ='11.1.4MD'!C67 | G7: =D7/(C7-F7)
B8: TS - Procesos prioritarios | C8: 91 | D8: ='11.1.5.PP'!C115 | E8: ='11.1.5.PP'!C116 | F8: ='11.1.5.PP'!C117 | G8: =D8/(C8-F8)
B9: TS - Historia clinica y registros | C9: 50 | D9: ='11.1.6.HCR'!C64 | E9: ='11.1.6.HCR'!C65 | F9: ='11.1.6.HCR'!C66 | G9: =D9/(C9-F9)
B10: TS - Interdependencia | C10: 5 | D10: ='11.1.7INT'!C12 | E10: ='11.1.7INT'!C13 | F10: ='11.1.7INT'!C14 | G10: =D10/(C10-F10)
B23: Grupo consulta externa | C23: Total criterios | D23: C | E23: NC | F23: NA | G23: Cumplimiento
B24: Servicio de consulta externa general | C24: 95 | D24: ='11.2.1.S_CE_G'!C161 | E24: ='11.2.1.S_CE_G'!C162 | F24: ='11.2.1.S_CE_G'!C163 | G24: =D24/(C24-F24)
B25: Servicio de consulta externa especializada | C25: 39 | D25: ='11.2.2.S_CE_E'!C94 | E25: ='11.2.2.S_CE_E'!C95 | F25: ='11.2.2.S_CE_E'!C96 | G25: =D25/(C25-F25)
B26: Servicio de vacunación | C26: 57 | D26: ='11.2.3.S_CE_V'!C84 | E26: ='11.2.3.S_CE_V'!C85 | F26: ='11.2.3.S_CE_V'!C86 | G26: =D26/(C26-F26)
B27: Servicio de seguridad y salud en el trabajo | C27: 29 | D27: ='11.2.4.S_CE_SST'!C56 | E27: ='11.2.4.S_CE_SST'!C57 | F27: ='11.2.4.S_CE_SST'!C58 | G27: =D27/(C27-F27)
B40: Grupo apoyo diagnóstico y complementación terapéutica | C40: Total criterios | D40: C | E40: NC | F40: NA | G40: Cumplimiento
B41: Servicio de terapias | C41: 44 | D41: ='11.3.1.S_TR'!C80 | E41: ='11.3.1.S_TR'!C81 | F41: ='11.3.1.S_TR'!C82 | G41: =D41/(C41-F41)
B42: Servicio farmacéutico | C42: 38 | D42: =' 11.3.2.SF'!C74 | E42: =' 11.3.2.SF'!C75 | F42: =' 11.3.2.SF'!C76 | G42: =D42/(C42-F42)
B43: Servicio de radiología odontológica | C43: 44 | D43: ='11.3.3.S_Rx_OD'!C72 | E43: ='11.3.3.S_Rx_OD'!C73 | F43: ='11.3.3.S_Rx_OD'!C74 | G43: =D43/(C43-F43)
B44: Servicio de imágenes diagnósticas | C44: =88+31 | D44: ='11.3.4.S_IDx'!C218 | E44: ='11.3.4.S_IDx'!C219 | F44: ='11.3.4.S_IDx'!C220 | G44: =D44/(C44-F44)
B45: Servicio de medicina nuclear | C45: 63 | D45: =' 11.3.5.S_MNuc'!C102 | E45: =' 11.3.5.S_MNuc'!C103 | F45: =' 11.3.5.S_MNuc'!C104 | G45: =D45/(C45-F45)
B46: Servicio de radioterapia | C46: 82 | D46: ='11.3.6.S_Radio'!C118 | E46: ='11.3.6.S_Radio'!C119 | F46: ='11.3.6.S_Radio'!C120 | G46: =D46/(C46-F46)
B47: Servicio de quimioterapia | C47: 80 | D47: ='11.3.7.S_Quimio'!C110 | E47: ='11.3.7.S_Quimio'!C111 | F47: ='11.3.7.S_Quimio'!C112 | G47: =D47/(C47-F47)
B48: Servicio de diagnóstico vascular 1 | C48: 33 | D48: ='11.3.8 S_Dx VASC'!C56 | E48: ='11.3.8 S_Dx VASC'!C57 | F48: ='11.3.8 S_Dx VASC'!C58 | G48: =D48/(C48-F48)
B49: Servicio de diagnóstico vascular 2 | C49: 33 | D49: ='11.3.8 S_Dx VASC'!#REF! | E49: ='11.3.8 S_Dx VASC'!#REF! | F49: ='11.3.8 S_Dx VASC'!#REF! | G49: =D49/(C49-F49)
B50: Servicio de diagnóstico vascular 3 | C50: 33 | D50: ='11.3.8 S_Dx VASC'!#REF! | E50: ='11.3.8 S_Dx VASC'!#REF! | F50: ='11.3.8 S_Dx VASC'!#REF! | G50: =D50/(C50-F50)
B51: Servicio de diagnóstico vascular 4 | C51: 33 | D51: ='11.3.8 S_Dx VASC'!#REF! | E51: ='11.3.8 S_Dx VASC'!#REF! | F51: ='11.3.8 S_Dx VASC'!#REF! | G51: =D51/(C51-F51)
B52: Servicio de diagnóstico vascular 5 | C52: 33 | D52: ='11.3.8 S_Dx VASC'!#REF! | E52: ='11.3.8 S_Dx VASC'!#REF! | F52: ='11.3.8 S_Dx VASC'!#REF! | G52: =D52/(C52-F52)
B53: Servicio de diagnóstico vascular 6 | C53: 33 | D53: ='11.3.8 S_Dx VASC'!#REF! | E53: ='11.3.8 S_Dx VASC'!#REF! | F53: ='11.3.8 S_Dx VASC'!#REF! | G53: =D53/(C53-F53)
B54: Servicio de diagnóstico vascular 7 | C54: 33 | D54: ='11.3.8 S_Dx VASC'!#REF! | E54: ='11.3.8 S_Dx VASC'!#REF! | F54: ='11.3.8 S_Dx VASC'!#REF! | G54: =D54/(C54-F54)
B55: Servicio de hemodinamia e intervencionismo | C55: 91 | D55: ='11.3.9S_HI'!C119 | E55: ='11.3.9S_HI'!C120 | F55: ='11.3.9S_HI'!C121 | G55: =D55/(C55-F55)
B56: Servicio de gestión pre transfusional | C56: 40 | D56: ='11.3.10 S_GPT'!C50 | E56: ='11.3.10 S_GPT'!C51 | F56: ='11.3.10 S_GPT'!C52 | G56: =D56/(C56-F56)
B57: Servicio de toma de muestras de laboratorio clínico | C57: 29 | D57: ='11.3.11.S_TMLC'!C48 | E57: ='11.3.11.S_TMLC'!C49 | F57: ='11.3.11.S_TMLC'!C50 | G57: =D57/(C57-F57)
B58: Servicio de laboratorio clínico | C58: 59 | D58: ='11.3.12.S_LC'!C81 | E58: ='11.3.12.S_LC'!C82 | F58: ='11.3.12.S_LC'!C83 | G58: =D58/(C58-F58)
B59: Servicio de toma de muestras de cuello uterino y ginecológicas | C59: 42 | D59: =' 11.3.13 S_TM_CU'!C60 | E59: =' 11.3.13 S_TM_CU'!C61 | F59: =' 11.3.13 S_TM_CU'!C62 | G59: =D59/(C59-F59)
B60: Servicio de laboratorio de citologías cérvico-uterinas | C60: 32 | D60: ='11.3.14.S_LCU'!C55 | E60: ='11.3.14.S_LCU'!C56 | F60: ='11.3.14.S_LCU'!C57 | G60: =D60/(C60-F60)
B61: Servicio de laboratorio de histotecnología | C61: 33 | D61: ='11.3.15.S_LHT'!C46 | E61: ='11.3.15.S_LHT'!C47 | F61: ='11.3.15.S_LHT'!C48 | G61: =D61/(C61-F61)
B62: Servicio de patología | C62: 51 | D62: ='11.3.16.S_LPT'!C75 | E62: ='11.3.16.S_LPT'!C76 | F62: ='11.3.16.S_LPT'!C77 | G62: =D62/(C62-F62)
B63: Servicio de diálisis | C63: 100 | D63: ='11.3.17.S_Dial'!C127 | E63: ='11.3.17.S_Dial'!C128 | F63: ='11.3.17.S_Dial'!C129 | G63: =D63/(C63-F63)
B66: Grupo de internación | C66: Total criterios | D66: C | E66: NC | F66: NA | G66: Cumplimiento
B67: Servicio de hospitalización | C67: 183 | D67: ='11.4.1.S_HP'!C266 | E67: ='11.4.1.S_HP'!C267 | F67: ='11.4.1.S_HP'!C268 | G67: =D67/(C67-F67)
B68: Servicio de hospitalización paciente crónico | C68: 167 | D68: ='11.4.2.S_HP_PC'!C247 | E68: ='11.4.2.S_HP_PC'!C248 | F68: ='11.4.2.S_HP_PC'!C249 | G68: =D68/(C68-F68)
...

Sheet 11.1.1TH
B1: VOLVER A TABLA DE CONTENIDO
B2: Estandar de Talento Humano
A3: Estandar | B3: Criterios | C3: Estado | D3: Comentarios | E3: Concepto preauditoría (QF)
A4: TSTH | B4: 1. El talento humano en salud y otros profesionales que se relacionan con la atención o resultados en salud de los usuarios, cuentan con los titulos, según aplique, de educación superior o certificados de aptitud ocupacional, expedidos por la entidad educativa competente. En el caso de títulos o certificados obtenidos en el extranjero, copia de la resolución de convalidación expedida por el Ministerio de Educación Nacional | C4: NC | D4: La respuesta enumera los cargos (QF director técnico, regentes, auxiliares) pero no aporta hojas de vida, diplomas ni certificados de aptitud ocupacional. No permite verificar que el perfil de cada cargo cumpla lo exigido para el SF; se requieren los soportes académicos de todo el personal del servicio. | E4: No evidenciado
A5: TSTH | B5: 2. El talento humano en salud cuenta con copia de la resolución de autorización del ejercicio expedido por la autoridad competente o inscripción e en el ReTHUS | C5: NC | D5: Se menciona la consulta en ReTHUS sin relacionar nombres ni resultados. Se requiere el listado del personal del SF con su número de inscripción en ReTHUS o resolución de autorización del ejercicio, y la copia en cada hoja de vida. | E5: No evidenciado
A6: TSTH | B6: 3. El prestador de servicios de salud determina la cantidad necesaria de talento humano requerido para cada uno de los servicios ofertados y prestados, de acuerdo con la capacidad instalada, la relación entre la oferta y demanda, la oportunidad en la prestación, tiempo de la atención y el riesgo en la atención. Este criterio no aplica para profesionales independientes de salud | C6: NC | D6: La respuesta describe qué debería contener el estudio de cargas, pero no evidencia que exista ni su resultado. No permite verificar la cobertura 24 h del SF para hospitalización y urgencias ni la disponibilidad del QF. Se requieren el documento de suficiencia de talento humano del SF y los cuadros de turno. | E6: No evidenciado
A7: TSTH | B7: 4. El prestador de servicios de salud que actúe como escenario de práctica formativa en el área de la salud, cuenta con:
A8: TSTH | B8: 4.1. Convenio vigente con la institución educativa autorizada por la entidad competente | C8: NC | D8: La calificación NA se basa en un supuesto (que el SF no es escenario de práctica), no en información confirmada. Debe verificarse si hay estudiantes (QF, regencia de farmacia, SENA) en el SF; si los hay, se requieren convenio docencia-servicio vigente, mecanismo de supervisión y estudio de capacidad. | E8: No evidenciado
A9: TSTH | B9: 4.2. Información documentada de los mecanismos de supervisión permanente del personal en entrnamiento | C9: NC | D9: La calificación NA se basa en un supuesto (que el SF no es escenario de práctica), no en información confirmada. Debe verificarse si hay estudiantes (QF, regencia de farmacia, SENA) en el SF; si los hay, se requieren convenio docencia-servicio vigente, mecanismo de supervisión y estudio de capacidad. | E9: No evidenciado
A10: TSTH | B10: 4.3. Estudio de la capacidad instalada en el cual se dtermine el número máximo de estudiantes que simultaneamente puedan acceder por programa de formación y por jornada, para cada uno de los servicios que se utilicen como escenarios de práctica formativa en el área de la salud, estudio que debe ser elaborado teniendo en cuenta los "lineamientos de referencia para la asignación de cupos de estudiantes en escenarios clinicos" publicados por el Ministerio de Salud y Protección Social | C10: NC | D10: La calificación NA se basa en un supuesto (que el SF no es escenario de práctica), no en información confirmada. Debe verificarse si hay estudiantes (QF, regencia de farmacia, SENA) en el SF; si los hay, se requieren convenio docencia-servicio vigente, mecanismo de supervisión y estudio de capacidad. | E10: No evidenciado
A11: TSTH | B11: 5. En los servicios de salud diferentes a los servicios de consulta externa especializada de dolor y cuidado paliativo, donde se atienden pacientes con enfermedades terminales, crónicas, degenerativas e irreversibles, a los cuales se les decida como conducta médica: como parte del plan integral de cuidado que gestiona el equipo de salud, o por solicitud del paciente; el manejo de dolor y cuidado paliativo, el profesional en medicina tratante cuenta con constancia de asistencia en las acciones de formación continua en el manejo de dolor y cuidado paliativo, cuando no sea especialista en dolor y cuidado paliativo | C11: NA | D11: No aplica al servicio farmacéutico: dirigido a profesionales de medicina tratantes en manejo de dolor y cuidado paliativo. | E11: No aplica
A12: TSTH | B12: 6. El talento humano en salud de los servicios de atención del parto, cuidado intensivo y cuidado intermedio neonatal, pediátrico y adultos, cuentan con constancia de asistencia en las acciones de formación continua para la gestión del duelo | C12: NA | D12: No aplica al servicio farmacéutico: dirigido al talento humano de atención del parto y cuidado intensivo/intermedio (gestión del duelo). | E12: No aplica
A13: TSTH | B13: 7. En los servicios de salud donde se realicen imagenes diagnósticas por ultrasonido, cuenta con médico especialista en radiologia e imagenes diagnósticas también podrán realizar imagenes diagnósticas aquellos médicos especialistas, quienes en su pensum o formación académica hayan adquirido los conocimientos del manejo e interpretación del espectro electromagnetico, del ultrasonido especialmente, así como de la radiaciones ionizantes para establecer el diagnóstico o el tratamiento de las enfermedades inherentes a su especialidad, para lo cual deberá acreditar el respectivo certificado. | C13: NA | D13: No aplica al servicio farmacéutico: aplica a servicios de imágenes diagnósticas por ultrasonido. | E13: No aplica
A14: TSTH | B14: 8. Los profesionales de la medicina de los servicios de hospitalización de baja, mediana y alta complejidad, hospitalización paciente crónico con y sin ventilador, cuidados intensivos neonatales, pediátricos y adultos; urgencias, y servicios del grupo quirurgico en modalidad intramural,cuentan con certificación vigente de aprobación de la evaluación de competencias esenciales para el cuidado de la donante expedida por el Instituto Nacional de Salud. | C14: NA | D14: No aplica al servicio farmacéutico: dirigido a profesionales de medicina de hospitalización, UCI, urgencias y cirugía (competencias en cuidado del donante - INS). | E14: No aplica
A15: TSTH | B15: 9. Las instituciones prestadoras de servicios de salud con servicios de cuidado intensivo pediatrico y adulto que adicionalmente habiliten servicio quirurgico de neurocirugía, tienen disponibilidad de coordinador operativo de trasplantes. | C15: NA | D15: No aplica al servicio farmacéutico: aplica a IPS con UCI y neurocirugía (coordinador operativo de trasplantes). | E15: No aplica
A16: TSTH | B16: 10. El talento humano en salud de los servicios de salud de los grupos de consulta externa, internación y el servicio de urgencias, cuentan con constancia de asistencia en las acciones de formación continua en la atención integral en salud de las personas victimas de violencia sexual. | C16: NA | D16: No aplica al servicio farmacéutico: dirigido a consulta externa, internación y urgencias (atención a víctimas de violencia sexual). El SF sí debe garantizar la disponibilidad del kit de profilaxis post-exposición. | E16: No aplica
A17: TSTH | B17: 11. El talento humano en salud de los servicios de transporte asistencial, atención prehospitalaria y urgencias, cuentasn con constancia de asistencia en las acciones de formación continua en la atención a personas víctimas de ataques con agentes químicos. | C17: NA | D17: No aplica al servicio farmacéutico: dirigido a transporte asistencial, APH y urgencias (víctimas de agentes químicos). | E17: No aplica
A18: TSTH | B18: 12. Cuando en un servicio de salud se realicen "pruebas en punto de atención del paciente - (point of care testing - POCT)", el talento humano en salud qeu las realice, a excepción del profesional en bacteriologia cuenta con constancia de asistencia en las acciones de formación continua en la atención a personas víctimas de ataques con agentes químicos. | C18: NA | D18: No aplica al servicio farmacéutico: en la farmacia no se realizan pruebas en punto de atención (POCT). | E18: No aplica
A19: TSTH | B19: 13. Procedimientos bajo sedación:
A20: TSTH | B20: 13.1 Cuando fuera de salas de cirugía, se realicen procedimientos bajo sedación Grado I y II, adicional al profesional de salud que realiza el procedimiento, cuenta con:
A21: TSTH | B21: 13.1.1. Profesional en la medicina especialista en anestesiologia, o profesional de la medicina o profesional en odontologia, según aplique, el cual será el encargado de administrar el medicamento y realizar el monitoreo continuo del paciente (registro de signos vitales y la respuesta a la sedación) | C21: NA | D21: No aplica al servicio farmacéutico: en la farmacia no se realizan procedimientos bajo sedación. | E21: No aplica
A22: TSTH | B22: 13.1.2. Todos los profesionales, a excepción del profesional de la medicina especialista en anestesiologia, deben demostrar constancia de asistencia a curso de formación continua en soporte vital básico y sedación | C22: NA | D22: No aplica al servicio farmacéutico: en la farmacia no se realizan procedimientos bajo sedación. | E22: No aplica
A23: TSTH | B23: 13.1.3 Para sedacción con óxido nitroso en odontologia, el profesional de la odontología cuenta con constancia de asistencia en las acciones de formación continua para uso clínico y práctico de este gas. | C23: NA | D23: No aplica al servicio farmacéutico: en la farmacia no se realizan procedimientos bajo sedación. | E23: No aplica
A24: TSTH | B24: 13.2. Cuando fuera de las salas de cirugia, se realicen procedimientos bajo sedación grado III, adicional al profesional de salud que realiza el procedimiento, cuenta con profesional de la medicina con especialidad médico - quirúrgica, quién será el responsable de administrar la sedación | C24: NA | D24: No aplica al servicio farmacéutico: en la farmacia no se realizan procedimientos bajo sedación. | E24: No aplica
A25: TSTH | B25: 13.3. Cuando fuera de las salas de cirugía, se realicen procedimientos bajo sedación grado IV, adicional al profesional de salud que realiza el procedimiento, cuenta con profesional de la medicina especialisa en anestesiologia, quién será el responsable de administrar la sedación | C25: NA | D25: No aplica al servicio farmacéutico: en la farmacia no se realizan procedimientos bajo sedación. | E25: No aplica
A26: TSTH | B26: 13.4 Cuenta con profesional de la medicina especialista en anestesiologia cuando la atención de trate de pacientes con caracteristicas particulares: poco colaboradores; edades extremas; con enfermedades severas:cardíacas, pulmonares, hepáticas, renales o del sistema nervioso central;cualquier alteración del grado de consciencia, con obesidad mórbida, con apnea del sueño, embarazadas, o quienes abusan del alcohol o de las drogas; antecedentes de sedación fallida o que presentaron efectos adversos a algún medicamento utilizado en la sedación, por tener un elevado riesgo de desarrollar complicaciones relacionadas con la sedación analgesia | C26: NA | D26: No aplica al servicio farmacéutico: en la farmacia no se realizan procedimientos bajo sedación. | E26: No aplica
A27: TSTH | B27: Modalidad de telemedicina prestador remisor - prestador de referencia
A28: TSTH | B28: 14. Adicional a los criterios del estándar de talento humano enunciados que le aplique, el talento humano en salud que preste directamente un servicio de salud bajo la modalidad telemedicina cuentan con constancia de asistencia en las acciones de formación continua en el manejo de tecnología utilizada por el prestador, los procesos y herramientas inherentes a la prestación de servicios bajo esta modalidad | C28: NA | D28: No aplica: el servicio farmacéutico no está habilitado en modalidad telemedicina (verificar en el REPS). | E28: No aplica
B30: CUMPLE | C30: =COUNTIF($C$4:$C$28,"C")
B31: NO CUMPLE | C31: =COUNTIF($C$4:$C$28,"NC")
B32: NO APLICA | C32: =COUNTIF($C$4:$C$28,"NA")

Sheet 11.1.2.INF
B1: VOLVER A TABLA DE CONTENIDO
B2: Estandar de Infraestructura
A3: Estandar | B3: Criterios | C3: Estado | D3: Comentarios | E3: Concepto preauditoría (QF)
A4: TSINF | B4: Edificaciones de uso exclusivo en salud
A5: TSINF | B5: 1. Los servicios de salud de urgencias, de atención del parto, hospitalarios y de cirugía que realicen procedimientos quirúrgicos no ambulatorios, solo se pueden prestar en edificaciones de uso exclusivo de salud. | C5: NC | D5: La respuesta afirma uso exclusivo en salud sin aportar certificado de uso del suelo ni licencia de construcción. Es un criterio de la edificación que condiciona al SF; debe verificarse con el documento correspondiente. | E5: No evidenciado
A6: TSINF | B6: 2. Los servicios de salud de: urgencias, cirugía y del grupo de internación, así como en los servicios de salud donde se realice el proceso de esterilización, deben contar con ambiente de aseo de uso exclusivo | C6: NA | D6: No aplica al servicio farmacéutico: el ambiente de aseo exclusivo se exige a urgencias, cirugía, internación y esterilización. Verificar que la farmacia tenga acceso a cuarto de aseo con insumos propios. | E6: No aplica
A7: TSINF | B7: 3. Cuando en una edificación de uso exclusivo de salud funcione más de un prestador de servicios de salud con servicios de los grupos de consulta externa y apoyo diagnóstico y complementación terapeutica, cada prestador cuenta con infraestructura separada delimitada fisicamente. Se pueden compartir los siguientes ambientes y áreas: aseo, salas de espera y unidades sanitarias. | C7: NC | D7: El NA supone un único prestador en la edificación, sin evidencia que lo confirme. Verificar en REPS y en campo que no funcionen otros prestadores (p. ej. farmacias o laboratorios de terceros) en la misma edificación. | E7: No evidenciado
A8: TSINF | B8: 4. Las edificaciones donde se presten servicios de salud de urgencias y del grupo de internación, cuentan con tanque de almacenamientode agua para el consumo humano que garantice como mínimo una reserva de 24 horas de servicio continuo, calculando con base en el consumo de 600 lt por cama/camilla al día. | C8: NC | D8: No se aportan el cálculo de reserva de 24 h ni los certificados de lavado y desinfección del tanque. La información no permite verificar el criterio; requiere soporte documental y verificación física. | E8: No evidenciado
A9: TSINF | B9: 5. Cuando el prestador de servicios de salud cuente con mas de una infraestructura y estas se puedan vincular funcionalmente entre si, lo harán mediante tunel o puente cubierto, o muro(s) colindante(s) que cuenten con acceso (s) que intercomuniquen las infraestructuras, de uso exclusivo del prestador y adicionalmente cumplen con las siguientes caracteristicas: | C9: NC | D9: El NA se basa en el supuesto de una sola infraestructura, sin confirmar. Debe verificarse en REPS si la clínica tiene sedes o edificaciones vinculadas funcionalmente; si existen y el SF abastece entre ellas, el criterio aplica. | E9: No evidenciado
A10: TSINF | B10: 5.1. Ancho que permita la movilización de camas, camillas, sillas de ruedas, equipos biomédicos y personal para el traslado de los pacientes en condiciones seguras. | C10: NC | D10: El NA se basa en el supuesto de una sola infraestructura, sin confirmar. Debe verificarse en REPS si la clínica tiene sedes o edificaciones vinculadas funcionalmente; si existen y el SF abastece entre ellas, el criterio aplica. | E10: No evidenciado
A11: TSINF | B11: 5.2. El piso del túnel o puente debe ser uniforme y de material antideslizante o con elementos que garanticen esta propiedad en todo su recorrido, con pasamanos d a ambos lados y con protecciones laterales hacia espacios libres. | C11: NC | D11: El NA se basa en el supuesto de una sola infraestructura, sin confirmar. Debe verificarse en REPS si la clínica tiene sedes o edificaciones vinculadas funcionalmente; si existen y el SF abastece entre ellas, el criterio aplica. | E11: No evidenciado
A12: TSINF | B12: 5.3. Lo anterior siempre y cuando la norma urbanística de la jurisdicción donde se localizan las sedes hayan aprobado esta forma de vinculación funcional entre las mismas. | C12: NC | D12: El NA se basa en el supuesto de una sola infraestructura, sin confirmar. Debe verificarse en REPS si la clínica tiene sedes o edificaciones vinculadas funcionalmente; si existen y el SF abastece entre ellas, el criterio aplica. | E12: No evidenciado
A13: TSINF | B13: 5.4. Esta edificación se podrá habilitar como una o varias sedes, de acuerdo con lo que determine el prestador de servicios de salud | C13: NC | D13: El NA se basa en el supuesto de una sola infraestructura, sin confirmar. Debe verificarse en REPS si la clínica tiene sedes o edificaciones vinculadas funcionalmente; si existen y el SF abastece entre ellas, el criterio aplica. | E13: No evidenciado
A14: TSINF | B14: Edificaciones de uso mixto
A15: TSINF | B15: 6. Cuando en una edificación de uso mixto funcione más de un prestador de servicios de salud, cada uno cuenta con infraestructura separada y delimitada físicamente. Se pueden compartir las salas de espera y las unidades sanitarias. | C15: NC | D15: El NA depende de confirmar el uso exclusivo en salud (criterio 1), que no está evidenciado. Verificar junto con ese criterio. | E15: No evidenciado
A16: TSINF | B16: 7. En edificaciones de uso mixto pueden funsionar los prestadores de servicios de salud que oferten y presten servicios de los grupos de consulta externa. de apoyo diagnóstico y complementación terapeutica y los servicios del grupo quirurgico que realicen exclusivamente procedimientos de cirugia ambulatoria. | C16: NC | D16: El NA depende de confirmar el uso exclusivo en salud (criterio 1), que no está evidenciado. Verificar junto con ese criterio. | E16: No evidenciado
A17: TSINF | B17: Edificaciones de uso exclusivo en salud y edificaciones de uso mixto
A18: TSINF | B18: 8. Los prestadores de servicios de salud ubicados en edificaciones de hasta tres (3) pisos o niveles contados a partir del nivel más bajo construido, y que funcione en segundo o tercer nivel o piso, cuentan con ascensor o rampa o sistema alternativo de elevación. El sistema alternativo de elevación no puede ser utilizado cuando se presten servicios hospitalarios, cirugía, urgencias o de atención del parto. | C18: NC | D18: La respuesta es condicional ('si... marcar NA') y no indica en qué piso funciona el SF ni si hay ascensor o rampa. Debe precisarse la ubicación del SF y verificarse en campo el medio de acceso para el traslado de medicamentos e insumos. | E18: No evidenciado
A19: TSINF | B19: 9. Los sistemas alternativos de elevación deben cumplir con las siguientes condiciones:
A20: TSINF | B20: 9.1. Su ubicación no interfiera con el acceso y evacuación de los usuarios por las escaleras | C20: NC | D20: El NA supone que no se usan sistemas alternativos de elevación, sin confirmarlo. Verificar en campo; si el acceso al SF o el traslado de medicamentos a otros pisos depende de uno, el criterio aplica. | E20: No evidenciado
A21: TSINF | B21: 9.2. Estén disponibles tanto para el acceso como para la evacuación de los usuarios | C21: NC | D21: El NA supone que no se usan sistemas alternativos de elevación, sin confirmarlo. Verificar en campo; si el acceso al SF o el traslado de medicamentos a otros pisos depende de uno, el criterio aplica. | E21: No evidenciado
A22: TSINF | B22: 9.3. Su manejo sea autonomo | C22: NC | D22: El NA supone que no se usan sistemas alternativos de elevación, sin confirmarlo. Verificar en campo; si el acceso al SF o el traslado de medicamentos a otros pisos depende de uno, el criterio aplica. | E22: No evidenciado
A23: TSINF | B23: 9.4. Garanticen seguridad durante su uso | C23: NC | D23: El NA supone que no se usan sistemas alternativos de elevación, sin confirmarlo. Verificar en campo; si el acceso al SF o el traslado de medicamentos a otros pisos depende de uno, el criterio aplica. | E23: No evidenciado
A24: TSINF | B24: 10. Las edificaciones con más de tres (3) pisos o niveles, contados a partir del nivel más bajo construido, cuentan con ascensor. | C24: NC | D24: Respuesta condicional; no informa el número de pisos de la edificación. Debe precisarse y verificarse en campo la existencia del ascensor si la edificación supera tres pisos. | E24: No evidenciado
A25: TSINF | B25: 11. En edificaciones donde se presten servicios de los grupos de internación, atención del parto, quirurgicos o urgencias para la movilización de pacientes en camilla, la cabina de los ascensores debe tener las dimensiones interiores mínimas de 2.20 de profundidad y de 1.20 ancho, que garanticen el traslado seguro de los pacientes. Las dimensiones de la cabina podrán ser variables en el o los ascensores que el prestador determine para la movilización de usuarios a pie o en silla de ruedas. | C25: NC | D25: Respuesta condicional; no informa si hay ascensor ni las dimensiones de la cabina. Es un criterio de la edificación, no específico del SF; debe verificarse en campo con medición. | E25: No evidenciado
A26: TSINF | B26: 12. Si se tienen escaleras o rampas, el piso debe ser uniforme y de material antideslizante o con elementos que garanticen esta propiedad en todo su recorrido, con pasamanos de preferencia a ambos lados y con protecciones laterales hacia espacios libres. | C26: NC | D26: Afirmación sin evidencia. Requiere verificación física de pisos antideslizantes, pasamanos y protecciones laterales en escaleras y rampas de acceso al SF. | E26: No evidenciado
A27: TSINF | B27: 13. Las edificaciones donde se presten servicios de salud cuentan con suministro de agua, energia eléctrica, conexión a la red de alcantarillado y sistemas de comunicaciones. | C27: NC | D27: No se aportan soportes de servicios públicos. Se verifica con recibos vigentes y observación en campo; debe confirmarse también la conectividad que requiere el software de inventario y dispensación del SF. | E27: No evidenciado
A28: TSINF | B28: 14. En edificaciones donde se presten servicios de cirugía, atención del parto, laboratorio clínico, urgencias, gestión pre transfusional, dialisis, hospitalarios, imagénes diagnósticas, vacunación, servicio farmaceutico y los que requieran cadena de frio, cuentan con planta electrica. | C28: NC | D28: Criterio crítico para el SF porque protege la cadena de frío. La respuesta no evidencia que exista la planta ni que cubra neveras y aire acondicionado de farmacia. Se requieren ficha técnica, identificación de los circuitos respaldados, registros de pruebas periódicas y mantenimiento. | E28: No evidenciado
A29: TSINF | B29: 15. El prestador de servicios de salud que utilice equipos generadores de radiaciones ionizantes cuenta con licencia de práctica médica vigente expedida por la entidad competente. | C29: NA | D29: No aplica al servicio farmacéutico: la licencia de práctica médica para radiaciones ionizantes aplica a imágenes diagnósticas; se evalúa en ese servicio. | E29: No aplica
A30: TSINF | B30: 16. El prestador de servicios de salud que utilice fuentes radiactivas cuenta con autorización vigente de empleo de material radiactivo, expedida por la entidad reguladora competente | C30: NA | D30: No aplica al servicio farmacéutico: la farmacia no utiliza fuentes radiactivas. | E30: No aplica
A31: TSINF | B31: 17. Cada prestador de servicios de salud debe contar con el respectivo concepto sanitario que dé cumplimiento a lo establecido en la normatividad sanitaria vigente en aspectos tales como agua para consumo humano, gestión de residuos, control de vectores, orden y aseo, condiciones locativas, entre otros. Este concepto será emitido por las autoridades sanitarias correspondientes, en el marco de sus competencias, y debe considerar los servicios de apoyo como lavanderia y servicio de alimentación. Cuando estos servicios de apoyo son contratados con terceros dichos proveedores deben contar con el concepto sanitario correspondiente a la actividad de bienes y servicios que presta. | C31: NC | D31: No se aporta el concepto sanitario ni su fecha. Debe verificarse que esté vigente, sea favorable y no tenga requerimientos pendientes relacionados con el SF o con la gestión de residuos de medicamentos. | E31: No evidenciado
A32: TSINF | B32: Generalidades de los ambientes y las áreas de los servicios y sus características
A33: TSINF | B33: 18. Las áreas y ambientes de todos los servicios de salud cuentan con ventilación natural o artificial. | C33: NC | D33: No se evidencia el tipo de ventilación del SF ni registros que demuestren control de temperatura. Verificar en campo el aire acondicionado y cruzarlo con los registros de temperatura del área. | E33: No evidenciado
A34: TSINF | B34: 19. Las áreas de circulación están libres de obstáculos de manera que permitan la movilización de pacientes, talento humano, usuarios y equipos biomédicos | C34: NC | D34: Solo puede confirmarse en campo. Hallazgo frecuente en farmacias: cajas en el piso o en pasillos que obstruyen la circulación; verificar el uso de estibas y que los pasillos estén libres. | E34: No evidenciado
A35: TSINF | B35: 20. Los ambientes y áreas que hagan parte de cualquier servicio de salud, deben permitir la instalación y movilización de equipos biomedicos y personal necesarios para la atención del paciente en condiciones de rutina o de emergencia. | C35: NC | D35: No se describen las dimensiones ni la distribución del SF. Debe verificarse en campo que los carros de distribución circulen sin obstáculos entre recepción, almacenamiento y dispensación. | E35: No evidenciado
A36: TSINF | B36: 21.En los servicios del grupo quirurgico, los ambientes y áreas clasificados como no restringidos, semirestringidos, deben señalizarse mediante la demarcación permanente en piso con material lavable y resistente al tráfico pesado, utilizando los siguientes colores | C36: NA | D36: No aplica al servicio farmacéutico: la demarcación por colores (verde, amarillo, rojo) aplica a los servicios del grupo quirúrgico. | E36: No aplica
A37: TSINF | B37: 21.1. Verde: Ambientes o áreas no restringidas | C37: NA | D37: No aplica al servicio farmacéutico: la demarcación por colores (verde, amarillo, rojo) aplica a los servicios del grupo quirúrgico. | E37: No aplica
A38: TSINF | B38: 21.2. Amarillo: Ambientes o áreas semi-restringidas | C38: NA | D38: No aplica al servicio farmacéutico: la demarcación por colores (verde, amarillo, rojo) aplica a los servicios del grupo quirúrgico. | E38: No aplica
A39: TSINF | B39: 21.3. Roja: Ambientes o áreas restringidas | C39: NA | D39: No aplica al servicio farmacéutico: la demarcación por colores (verde, amarillo, rojo) aplica a los servicios del grupo quirúrgico. | E39: No aplica
A40: TSINF | B40: 22. Cada uno de los pisos o niveles de la edificación cuenta con señalización y planos indicativos de las rutas de evacuación, salidas de emergencia y puntos de encuentro, visible al público en general. | C40: NC | D40: No se evidencian planos de evacuación ni señalización en el área del SF. Requiere verificación en campo. | E40: No evidenciado
...

Sheet 11.1.3.DOT
B1: VOLVER A TABLA DE CONTENIDO
B2: Estandar de Dotación
A3: Estandar | B3: Criterios | C3: Estado | D3: Comentarios | E3: Concepto preauditoría (QF)
A4: TSDOT | B4: 1. El prestador de servicios de salud cuenta con el registro de la relación de los equipos biomédicos requeridos para la prestación de servicios de salud, este registro cuenta como mínimo con la siguiente información:
A5: TSDOT | B5: 1.1. Nombre del equipo biomédico. | C5: NC | D5: La respuesta trata neveras, termohigrómetros y aire acondicionado como 'equipos biomédicos'; en sentido estricto son equipos de apoyo e instrumentos de medición. Debe definirse qué equipos biomédicos tiene el SF y aportar el inventario; si no tiene ninguno, sus equipos se controlan en el criterio 9 del SF (hoja 11.3.2). | E5: No evidenciado
A6: TSDOT | B6: 1.2. Marca. | C6: NC | D6: No se aporta el inventario, por lo que no es posible verificar el registro de la marca de los equipos del SF. | E6: No evidenciado
A7: TSDOT | B7: 1.3. Modelo. | C7: NC | D7: No se aporta el inventario, por lo que no es posible verificar el registro del modelo de los equipos del SF. | E7: No evidenciado
A8: TSDOT | B8: 1.4. Serie. | C8: NC | D8: No se aporta el inventario, por lo que no es posible verificar el registro de la serie de los equipos del SF. | E8: No evidenciado
A9: TSDOT | B9: 1.5. Registro sanitario para dispositivos médicos o permiso de comercialización para equipos biomédicos de tecnología controlada, cuando lo requiera. | C9: NC | D9: No se identifica qué equipos del SF requieren registro sanitario o permiso de comercialización. Termohigrómetros y aires acondicionados no lo requieren; debe precisarse equipo por equipo y aportar el soporte de los que sí. | E9: No evidenciado
A10: TSDOT | B10: 1.6. Clasificación por riesgo, cuando el equipo lo requiera. | C10: NC | D10: No se evidencia la clasificación por riesgo, que solo aplica a los equipos que sean dispositivos médicos. Debe precisarse en el inventario. | E10: No evidenciado
A11: TSDOT | B11: 2. El prestador de servicios de salud garantiza las condiciones técnicas de calidad de los equipos biomédicos, para lo cual cuenta con:
A12: TSDOT | B12: 2.1. Programa de mantenimiento preventivo de los equipos biomédicos, que incluya el cumplimiento de las recomendaciones establecidas por el fabricante o de acuerdo con el protocolo de mantenimiento que tenga definido el prestador, éste último cuando no esté definido por el fabricante. | C12: NC | D12: Solo se menciona el cronograma. Debe demostrarse la ejecución: registros de mantenimiento de neveras y aire acondicionado, y certificados de calibración vigentes de los termohigrómetros emitidos por un laboratorio acreditado. Sin calibración, los registros de temperatura y humedad no son confiables. | E12: No evidenciado
A13: TSDOT | B13: 2.2. Hoja(s) de vida del(los) equipo(s) biomédico(s), con los registros de los mantenimientos preventivos y correctivos, según corresponda. | C13: NC | D13: No se aportan hojas de vida. Debe verificarse que cada equipo del SF tenga hoja de vida con los mantenimientos y las calibraciones registrados. | E13: No evidenciado
A14: TSDOT | B14: 3. El prestador de servicios de salud cuenta con un programa de capacitación en el uso de dispositivos médicos cuando éstos lo requieran, el cual puede ser desarrollado por el fabricante, importador o por el mismo prestador. | C14: NA | D14: No aplica al servicio farmacéutico: el personal de farmacia no usa dispositivos médicos en pacientes. Sí debe estar capacitado en el uso de neveras y data loggers (dejar registro). | E14: No aplica
A15: TSDOT | B15: 4. La dotación de los servicios de salud está en concordancia con lo definido por el prestador en el estándar de procesos prioritarios. | C15: NC | D15: La respuesta enumera la dotación esperada sin demostrar que exista. Debe verificarse en campo, contra el manual de procesos del SF, que la dotación corresponda a los procesos que realmente se ejecutan. | E15: No evidenciado
A16: TSDOT | B16: 5. La suficiencia de equipos biomédicos está relacionada con la frecuencia de uso de los mismo, incluyendo los tiempos del proceso de esterilización, cuando aplique. | C16: NC | D16: No se informa el número de neveras y termohigrómetros ni de las áreas o stocks a controlar. Debe verificarse que cada área de almacenamiento de medicamentos (farmacia, bodega, stocks de servicios) tenga su instrumento de medición. | E16: No evidenciado
A17: TSDOT | B17: 6. El mantenimiento de los equipos biomédicps es ejecutado por el talento humano profesional, tecnólogo o técnico en áreas relacionadas. Este mantenimiento puede ser realizado directamente por el prestador de servicios de salud o mediante contrato o convenio con un tercero. | C17: NC | D17: No se aporta contrato ni soporte de idoneidad del personal de mantenimiento. Se requieren el contrato con la empresa o la hoja de vida del técnico, y la verificación de las firmas en los reportes de mantenimiento. | E17: No evidenciado
A18: TSDOT | B18: 7. Los prestadores que oferten servicios de salud en modalidad extramural no pueden elaborar ni adaptar dispositivos médicos sobre medida. | C18: NA | D18: No aplica: el servicio farmacéutico no presta modalidad extramural (unidad móvil, jornada de salud ni domiciliaria). | E18: No aplica
A19: TSDOT | B19: 8. Los servicios de salud que requieren carro de paro, cuenta con la siguiente dotación:
A20: TSDOT | B20: 8.1. Desfibrilador bifásico con sistema de visualización integrado, capacidad de cardioversión, marcapasos transcutáneo y paletas para adultos y pediátricas según aplique. | C20: NA | D20: No aplica al servicio farmacéutico: la farmacia no requiere carro de paro. El SF sí define, repone y controla los medicamentos y dispositivos de los carros de paro de los demás servicios (ver hoja 11.1.4, criterios 11 y 12). | E20: No aplica
A21: TSDOT | B21: 8.2. Resucitador pulmonar manual. | C21: NA | D21: No aplica al servicio farmacéutico: la farmacia no requiere carro de paro. El SF sí define, repone y controla los medicamentos y dispositivos de los carros de paro de los demás servicios (ver hoja 11.1.4, criterios 11 y 12). | E21: No aplica
A22: TSDOT | B22: 8.3. Aspirador o sistema de vacío. | C22: NA | D22: No aplica al servicio farmacéutico: la farmacia no requiere carro de paro. El SF sí define, repone y controla los medicamentos y dispositivos de los carros de paro de los demás servicios (ver hoja 11.1.4, criterios 11 y 12). | E22: No aplica
A23: TSDOT | B23: 8.4. Monitor de signos vitales con accesorios que cuenta como mínimo con:
A24: TSDOT | B24: 8.4.1. Trazado electrocardiográfico si no está incorporado en el desfibrilador | C24: NA | D24: No aplica al servicio farmacéutico: la farmacia no requiere carro de paro. El SF sí define, repone y controla los medicamentos y dispositivos de los carros de paro de los demás servicios (ver hoja 11.1.4, criterios 11 y 12). | E24: No aplica
A25: TSDOT | B25: 8.4.2.Presión no invasiva | C25: NA | D25: No aplica al servicio farmacéutico: la farmacia no requiere carro de paro. El SF sí define, repone y controla los medicamentos y dispositivos de los carros de paro de los demás servicios (ver hoja 11.1.4, criterios 11 y 12). | E25: No aplica
A26: TSDOT | B26: 8.4.3. Saturación de oxígeno que puede estar integrado en el monitor o externo | C26: NA | D26: No aplica al servicio farmacéutico: la farmacia no requiere carro de paro. El SF sí define, repone y controla los medicamentos y dispositivos de los carros de paro de los demás servicios (ver hoja 11.1.4, criterios 11 y 12). | E26: No aplica
A27: TSDOT | B27: 8.4.4. Batería | C27: NA | D27: No aplica al servicio farmacéutico: la farmacia no requiere carro de paro. El SF sí define, repone y controla los medicamentos y dispositivos de los carros de paro de los demás servicios (ver hoja 11.1.4, criterios 11 y 12). | E27: No aplica
A28: TSDOT | B28: 8.5. Laringoscopio con hojas rectas y curvas para adultos y pediátricas, según aplique | C28: NA | D28: No aplica al servicio farmacéutico: la farmacia no requiere carro de paro. El SF sí define, repone y controla los medicamentos y dispositivos de los carros de paro de los demás servicios (ver hoja 11.1.4, criterios 11 y 12). | E28: No aplica
A29: TSDOT | B29: 8.6. Medicamentos, dispositivos médicos e insumos, definidos por el prestador. | C29: NA | D29: No aplica al servicio farmacéutico: la farmacia no requiere carro de paro. El SF sí define, repone y controla los medicamentos y dispositivos de los carros de paro de los demás servicios (ver hoja 11.1.4, criterios 11 y 12). | E29: No aplica
A30: TSDOT | B30: 9. Las instituciones prestadoras de servicios de salud con servicios de hospitalización, hospitalización paciente crónico con y sin ventilador, cuidado intensivo neonatal, pediátrico y adulto, urgencias y del grupo quirúrgico, en la modalidad intramural, cuentan con equipos de telecomunicaciones de doble via y conectividad para notificar a la Red de Donación y Trasplantes sobre la existencia de un posible donante. | C30: NA | D30: No aplica al servicio farmacéutico: los equipos para notificar a la Red de Donación y Trasplantes se evalúan a nivel institucional (hospitalización, urgencias, UCI y cirugía). | E30: No aplica
A31: TSDOT | B31: 10. Las instituciones prestadoras de servicios de salud con servicios de cuidado intensivo pediátrico y adulto que adicionalmente habiliten el servicio quirúrgico de neurocirugía, cuentan con equipo biomédico para realizar pruebas auxiliares en el diagnóstico de muerte encefálica, según lo documentado en el estándar de procesos prioritarios. | C31: NA | D31: No aplica al servicio farmacéutico: aplica a IPS con UCI y neurocirugía. | E31: No aplica
A32: TSDOT | B32: 11. En los sistemas centralizados de gases medicinales, se realiza el mantenimiento a los componentes del sistema por el personal capacitado por el fabricante. | C32: NA | D32: No aplica al servicio farmacéutico: el mantenimiento del sistema centralizado de gases medicinales se evalúa a nivel institucional. | E32: No aplica
A33: TSDOT | B33: 12. El prestador de servicios de salud que realice el proceso de esterilización en un área o ambiente dentro o fuera del servicio de salud cuenta con los equipos biomédicos y la dotación de acuerdo con el método utilizado. | C33: NA | D33: No aplica al servicio farmacéutico: en la farmacia no se realiza el proceso de esterilización. | E33: No aplica
A34: TSDOT | B34: 13. Si el prestador de servicios de salud no tiene habilitado el servicio de gestión pre transfusional, pero realiza procedimientos de transfusión sanguínea en alguno de sus servicios habilitados cuenta con:
A35: TSDOT | B35: 13.1. Nevera o depósito fria para el almacenamiento de sangre o de sus componentes con sistema de control de temperatura entre 1ºC y 6ºC y alarma audible o sistema de monitoreo que alerte cambios próximos al límite en que la sangre o sus componentes puedan deteriorarse. | C35: NA | D35: No aplica al servicio farmacéutico: la dotación para transfusiones aplica a los servicios donde se transfunde. | E35: No aplica
A36: TSDOT | B36: 13.2. Equipo para descongelar plasma, cuando se requiera, con sistema de control de temperatura. | C36: NA | D36: No aplica al servicio farmacéutico: la dotación para transfusiones aplica a los servicios donde se transfunde. | E36: No aplica
A37: TSDOT | B37: 13.3 Congelador para la conservación de plasma o crioprecipitados con registro y control de temperatura por debajo de -18ºC y sistema de alarma audible que alerte cambios próximos al límite en que el componente almacenado pueda deteriorarse, cuando se requiera. | C37: NA | D37: No aplica al servicio farmacéutico: la dotación para transfusiones aplica a los servicios donde se transfunde. | E37: No aplica
A38: TSDOT | B38: 13.4. Agitador o rotador de plaquetas con sistema de control de temperatura entre 20ºC y 24ºC cuando se requiera. | C38: NA | D38: No aplica al servicio farmacéutico: la dotación para transfusiones aplica a los servicios donde se transfunde. | E38: No aplica
A39: TSDOT | B39: 13.5. Nevera para transporte de componentes sanguíneos, donde se garantice la cadena de frío. | C39: NA | D39: No aplica al servicio farmacéutico: la dotación para transfusiones aplica a los servicios donde se transfunde. | E39: No aplica
A40: TSDOT | B40: 14. Los servicios de salud donde se realicen procedimientos bajo sedación fuera de salas de cirugía y monitorización electroencefalográfica con video y radio cuentan con carro de paro. | C40: NA | D40: No aplica al servicio farmacéutico: en la farmacia no se realizan procedimientos bajo sedación. | E40: No aplica
...

Sheet 11.1.4MD
B1: VOLVER A TABLA DE CONTENIDO
B2: Estandar de Medicamentos, dispositivos médicos e insumos
A3: Estandar | B3: Criterios | C3: Estado | D3: Comentarios | E3: Concepto preauditoría (QF)
A4: TSMD | B4: 1. El prestador de servicios de salud lleva registros con la información de todos los medicamentos para uso humano requeridos en la prestación de los servicios que oferte; dichos registros cuentan con la siguiente información:
A5: TSMD | B5: 1.1. Principio activo. | C5: NC | D5: El registro de principio activo se menciona como parte del inventario, sin aportar el listado básico ni una salida del sistema. Se requiere revisar una muestra del inventario del SF y confirmar que el campo esté completo y concuerde con el producto físico. | E5: No evidenciado
A6: TSMD | B6: 1.2. Forma farmacéutica. | C6: NC | D6: El registro de forma farmacéutica se menciona como parte del inventario, sin aportar el listado básico ni una salida del sistema. Se requiere revisar una muestra del inventario del SF y confirmar que el campo esté completo y concuerde con el producto físico. | E6: No evidenciado
A7: TSMD | B7: 1.3. Concentración | C7: NC | D7: El registro de concentración se menciona como parte del inventario, sin aportar el listado básico ni una salida del sistema. Se requiere revisar una muestra del inventario del SF y confirmar que el campo esté completo y concuerde con el producto físico. | E7: No evidenciado
A8: TSMD | B8: 1.4. Lote. | C8: NC | D8: El registro de lote se menciona como parte del inventario, sin aportar el listado básico ni una salida del sistema. Se requiere revisar una muestra del inventario del SF y confirmar que el campo esté completo y concuerde con el producto físico. | E8: No evidenciado
A9: TSMD | B9: 1.5. Fecha de vencimiento. | C9: NC | D9: El registro de fecha de vencimiento se menciona como parte del inventario, sin aportar el listado básico ni una salida del sistema. Se requiere revisar una muestra del inventario del SF y confirmar que el campo esté completo y concuerde con el producto físico. | E9: No evidenciado
A10: TSMD | B10: 1.6. Presentación comercial. | C10: NC | D10: El registro de presentación comercial se menciona como parte del inventario, sin aportar el listado básico ni una salida del sistema. Se requiere revisar una muestra del inventario del SF y confirmar que el campo esté completo y concuerde con el producto físico. | E10: No evidenciado
A11: TSMD | B11: 1.7. Unidad de medida. | C11: NC | D11: El registro de unidad de medida se menciona como parte del inventario, sin aportar el listado básico ni una salida del sistema. Se requiere revisar una muestra del inventario del SF y confirmar que el campo esté completo y concuerde con el producto físico. | E11: No evidenciado
A12: TSMD | B12: 1.8. Registro sanitario vigente o permiso cuando se autorice, expedido por el Invima. | C12: NC | D12: No se aporta evidencia de la verificación de registros sanitarios. Se requiere la consulta en INVIMA, con fecha, para una muestra de productos, y el control de registros vencidos o en trámite de renovación. Es un punto de alto riesgo en la visita. | E12: No evidenciado
A13: TSMD | B13: 2. Los dispositivos médicos de uso humano requeridos para la prestación de los servicios de salud cuentan con información documentada que dé cuenta de la verificación y seguimiento de la siguiente información:
A14: TSMD | B14: 2.1. Descripción. | C14: NC | D14: No se aporta el listado de dispositivos médicos, por lo que no es posible verificar el registro de la descripción. Se requiere revisar una muestra y cruzarla con el producto físico. | E14: No evidenciado
A15: TSMD | B15: 2.2. Marca del dispositivo. | C15: NC | D15: No se aporta el listado de dispositivos médicos, por lo que no es posible verificar el registro de la marca. Se requiere revisar una muestra y cruzarla con el producto físico. | E15: No evidenciado
A16: TSMD | B16: 2.3. Serie (cuando le aplique). | C16: NC | D16: No se aporta el listado de dispositivos médicos, por lo que no es posible verificar el registro de la serie. Aplica sobre todo a dispositivos seriados. Se requiere revisar una muestra y cruzarla con el producto físico. | E16: No evidenciado
